Workbook
Name conflict_and_fragility_1: Conflict!$J$7:$AA$225
Name food_security_1: Food!$J$7:$V$225
Name Health: Conflict!#REF!
Name Health: Food!#REF!
Name Health: Macro!#REF!
Name Health: 'Natural Hazard'!#REF!
Name Health: Socioeconomic!#REF!
Name health_1: Health!$J$7:$R$225
Name indicators_list: 'Data Dictionary'!$B$7:$R$35
Name macro_fiscal_1: Macro!$J$7:$P$225
Name natural_hazard_1: 'Natural Hazard'!$J$7:$X$225
Name reliabilitysheet: 'Compound Alert'!#REF!
Name reliabilitysheet_1: 'Data Reliability'!$E$5:$T$223
Name socioeconomic_vulnerability_1: Socioeconomic!$J$7:$T$225

Sheet Landing

Sheet Dashboard
B2: COMPOUND RISK MONITOR: Methodology Options
B4: Click on the rectangles, and then the appearing arrow, to see and select options. If display does not refresh you may need to enable automatic calculations (scroll to right for instructions).
B6: Snapshot | J6: Dimensions → Overall Dimensions
B7: Overall Alert is a synthesis of underlying vulnerability and emerging threat | J7: How to calculate overall alert dimensions from underlying vulnerability and emerging threat dimensions? (Will only effect Overall Alert snapshot)
B8: Overall Alert | G8: Select one | J8: AGGREGATE: Geometric Mean | O8: Select one
B10: Indicators → Dimensions | J10: Count medium values as half flags
B11: How to calculate underlying and emerging dimensions from indicators | J11: For overall alert, high values are >7 and medium values are >5. For underlying and emerging, high is 10, and medium is >7.
B12: Max value (default) Select the maximum value across the suite of grouped indicators. | G12: Select one | J12: Yes (default) | O12: Select one
B15: =CONCATENATE("— ",UPPER(B8)," — ") -> — OVERALL ALERT —
A40: Blank1 | B40: Country Name | C40: Country Code | D40: Region | E40: Lending Group | F40: Blank2 | G40: =CONCATENATE(B8, " Flags") -> Overall Alert Flags | I40: Blank3 | J40: Health | K40: Food Security | L40: Macro Fiscal | M40: Socioecon. Vulnerability | N40: Natural Hazards | O40: Conflict Fragility
A41: Blank1 | B41: Country Name | C41: Country Code | D41: Region | E41: Lending Group | F41: Blank2 | G41: Flags | H41: B1 | I41: Blank3 | J41: Health | K41: Food Security | L41: Macro Fiscal | M41: Socioecon Vulnerability | N41: Natural Hazards | O41: Conflict Fragility | P41: Blank4
A42: 1 | B42: ='Compound Alert'!B194 -> Chad | C42: ='Compound Alert'!C194 -> TCD | D42: ='Compound Alert'!D194 -> SSF Sub-Saharan Africa | E42: ='Compound Alert'!E194 -> IDA | F42: ='Compound Alert'!F194 -> 189 | G42: =IF($B$8="Overall Alert",'Compound Alert'!G194,IF($B$8="Underlying Vulnerability",'Compound Alert'!J194,IF($B$8="Emerging Threat",'Compound Alert'!M194))) -> 3.5 | H42: =IF($B$8="Overall Alert",'Compound Alert'!H194,IF($B$8="Underlying Vulnerability",'Compound Alert'!K194,IF($B$8="Emerging Threat",'Compound Alert'!N194))) -> 3.5 | I42: =ROUNDDOWN(G42,0) -> 3 | J42: =IF( $B$8="Overall Alert",IF( 'Compound Alert'!R194 >= 7, "HIGH",IF( 'Compound Alert'!R194 >= 5, "MED","LOW")), IF( $B$8="Underlying Vulnerability", IF( 'Compound Alert'!Y194 >= 10, "HIGH",IF( 'Compound Alert'!Y194 >= 7, "MED","LOW")),IF( $B$8="Emerging Threat", IF( 'Compound Alert'!AF194 >= 10, "HIGH",IF( 'Compound Alert'!AF194 >= 7, "MED","LOW"))))) -> HIGH | K42: =IF( $B$8="Overall Alert",IF( 'Compound Alert'!S194 >= 7, "HIGH",IF( 'Compound Alert'!S194 >= 5, "MED","LOW")), IF( $B$8="Underlying Vulnerability", IF( 'Compound Alert'!Z194 >= 10, "HIGH",IF( 'Compound Alert'!Z194 >= 7, "MED","LOW")),IF( $B$8="Emerging Threat", IF( 'Compound Alert'!AG194 >= 10, "HIGH",IF( 'Compound Alert'!AG194 >= 7, "MED","LOW"))))) -> HIGH | L42: =IF( $B$8="Overall Alert",IF( 'Compound Alert'!T194 >= 7, "HIGH",IF( 'Compound Alert'!T194 >= 5, "MED","LOW")), IF( $B$8="Underlying Vulnerability", IF( 'Compound Alert'!AA194 >= 10, "HIGH",IF( 'Compound Alert'!AA194 >= 7, "MED","LOW")),IF( $B$8="Emerging Threat", IF( 'Compound Alert'!AH194 >= 10, "HIGH",IF( 'Compound Alert'!AH194 >= 7, "MED","LOW"))))) -> MED | M42: =IF( $B$8="Overall Alert",IF( 'Compound Alert'!U194 >= 7, "HIGH",IF( 'Compound Alert'!U194 >= 5, "MED","LOW")), IF( $B$8="Underlying Vulnerability", IF( 'Compound Alert'!AB194 >= 10, "HIGH",IF( 'Compound Alert'!AB194 >= 7, "MED","LOW")),IF( $B$8="Emerging Threat", IF( 'Compound Alert'!AI194 >= 10, "HIGH",IF( 'Compound Alert'!AI194 >= 7, "MED","LOW"))))) -> LOW | N42: =IF( $B$8="Overall Alert",IF( 'Compound Alert'!V194 >= 7, "HIGH",IF( 'Compound Alert'!V194 >= 5, "MED","LOW")), IF( $B$8="Underlying Vulnerability", IF( 'Compound Alert'!AC194 >= 10, "HIGH",IF( 'Compound Alert'!AC194 >= 7, "MED","LOW")),IF( $B$8="Emerging Threat", IF( 'Compound Alert'!AJ194 >= 10, "HIGH",IF( 'Compound Alert'!AJ194 >= 7, "MED","LOW"))))) -> HIGH | O42: =IF( $B$8="Overall Alert",IF( 'Compound Alert'!W194 >= 7, "HIGH",IF( 'Compound Alert'!W194 >= 5, "MED","LOW")), IF( $B$8="Underlying Vulnerability", IF( 'Compound Alert'!AD194 >= 10, "HIGH",IF( 'Compound Alert'!AD194 >= 7, "MED","LOW")),IF( $B$8="Emerging Threat", IF( 'Compound Alert'!AK194 >= 10, "HIGH",IF( 'Compound Alert'!AK194 >= 7, "MED","LOW"))))) -> LOW
A43: 2 | B43: ='Compound Alert'!B181 -> Somalia | C43: ='Compound Alert'!C181 -> SOM | D43: ='Compound Alert'!D181 -> SSF Sub-Saharan Africa | E43: ='Compound Alert'!E181 -> IDA | F43: ='Compound Alert'!F181 -> 176 | G43: =IF($B$8="Overall Alert",'Compound Alert'!G181,IF($B$8="Underlying Vulnerability",'Compound Alert'!J181,IF($B$8="Emerging Threat",'Compound Alert'!M181))) -> 2.5 | H43: =IF($B$8="Overall Alert",'Compound Alert'!H181,IF($B$8="Underlying Vulnerability",'Compound Alert'!K181,IF($B$8="Emerging Threat",'Compound Alert'!N181))) -> 2.5 | I43: =ROUNDDOWN(G43,0) -> 2 | J43: =IF( $B$8="Overall Alert",IF( 'Compound Alert'!R181 >= 7, "HIGH",IF( 'Compound Alert'!R181 >= 5, "MED","LOW")), IF( $B$8="Underlying Vulnerability", IF( 'Compound Alert'!Y181 >= 10, "HIGH",IF( 'Compound Alert'!Y181 >= 7, "MED","LOW")),IF( $B$8="Emerging Threat", IF( 'Compound Alert'!AF181 >= 10, "HIGH",IF( 'Compound Alert'!AF181 >= 7, "MED","LOW"))))) -> LOW | K43: =IF( $B$8="Overall Alert",IF( 'Compound Alert'!S181 >= 7, "HIGH",IF( 'Compound Alert'!S181 >= 5, "MED","LOW")), IF( $B$8="Underlying Vulnerability", IF( 'Compound Alert'!Z181 >= 10, "HIGH",IF( 'Compound Alert'!Z181 >= 7, "MED","LOW")),IF( $B$8="Emerging Threat", IF( 'Compound Alert'!AG181 >= 10, "HIGH",IF( 'Compound Alert'!AG181 >= 7, "MED","LOW"))))) -> HIGH | L43: =IF( $B$8="Overall Alert",IF( 'Compound Alert'!T181 >= 7, "HIGH",IF( 'Compound Alert'!T181 >= 5, "MED","LOW")), IF( $B$8="Underlying Vulnerability", IF( 'Compound Alert'!AA181 >= 10, "HIGH",IF( 'Compound Alert'!AA181 >= 7, "MED","LOW")),IF( $B$8="Emerging Threat", IF( 'Compound Alert'!AH181 >= 10, "HIGH",IF( 'Compound Alert'!AH181 >= 7, "MED","LOW"))))) -> MED | M43: =IF( $B$8="Overall Alert",IF( 'Compound Alert'!U181 >= 7, "HIGH",IF( 'Compound Alert'!U181 >= 5, "MED","LOW")), IF( $B$8="Underlying Vulnerability", IF( 'Compound Alert'!AB181 >= 10, "HIGH",IF( 'Compound Alert'!AB181 >= 7, "MED","LOW")),IF( $B$8="Emerging Threat", IF( 'Compound Alert'!AI181 >= 10, "HIGH",IF( 'Compound Alert'!AI181 >= 7, "MED","LOW"))))) -> LOW | N43: =IF( $B$8="Overall Alert",IF( 'Compound Alert'!V181 >= 7, "HIGH",IF( 'Compound Alert'!V181 >= 5, "MED","LOW")), IF( $B$8="Underlying Vulnerability", IF( 'Compound Alert'!AC181 >= 10, "HIGH",IF( 'Compound Alert'!AC181 >= 7, "MED","LOW")),IF( $B$8="Emerging Threat", IF( 'Compound Alert'!AJ181 >= 10, "HIGH",IF( 'Compound Alert'!AJ181 >= 7, "MED","LOW"))))) -> HIGH | O43: =IF( $B$8="Overall Alert",IF( 'Compound Alert'!W181 >= 7, "HIGH",IF( 'Compound Alert'!W181 >= 5, "MED","LOW")), IF( $B$8="Underlying Vulnerability", IF( 'Compound Alert'!AD181 >= 10, "HIGH",IF( 'Compound Alert'!AD181 >= 7, "MED","LOW")),IF( $B$8="Emerging Threat", IF( 'Compound Alert'!AK181 >= 10, "HIGH",IF( 'Compound Alert'!AK181 >= 7, "MED","LOW"))))) -> LOW
A44: 3 | B44: ='Compound Alert'!B174 -> Sudan | C44: ='Compound Alert'!C174 -> SDN | D44: ='Compound Alert'!D174 -> SSF Sub-Saharan Africa | E44: ='Compound Alert'!E174 -> IDA | F44: ='Compound Alert'!F174 -> 169 | G44: =IF($B$8="Overall Alert",'Compound Alert'!G174,IF($B$8="Underlying Vulnerability",'Compound Alert'!J174,IF($B$8="Emerging Threat",'Compound Alert'!M174))) -> 1.5 | H44: =IF($B$8="Overall Alert",'Compound Alert'!H174,IF($B$8="Underlying Vulnerability",'Compound Alert'!K174,IF($B$8="Emerging Threat",'Compound Alert'!N174))) -> 1.5 | I44: =ROUNDDOWN(G44,0) -> 1 | J44: =IF( $B$8="Overall Alert",IF( 'Compound Alert'!R174 >= 7, "HIGH",IF( 'Compound Alert'!R174 >= 5, "MED","LOW")), IF( $B$8="Underlying Vulnerability", IF( 'Compound Alert'!Y174 >= 10, "HIGH",IF( 'Compound Alert'!Y174 >= 7, "MED","LOW")),IF( $B$8="Emerging Threat", IF( 'Compound Alert'!AF174 >= 10, "HIGH",IF( 'Compound Alert'!AF174 >= 7, "MED","LOW"))))) -> LOW | K44: =IF( $B$8="Overall Alert",IF( 'Compound Alert'!S174 >= 7, "HIGH",IF( 'Compound Alert'!S174 >= 5, "MED","LOW")), IF( $B$8="Underlying Vulnerability", IF( 'Compound Alert'!Z174 >= 10, "HIGH",IF( 'Compound Alert'!Z174 >= 7, "MED","LOW")),IF( $B$8="Emerging Threat", IF( 'Compound Alert'!AG174 >= 10, "HIGH",IF( 'Compound Alert'!AG174 >= 7, "MED","LOW"))))) -> HIGH | L44: =IF( $B$8="Overall Alert",IF( 'Compound Alert'!T174 >= 7, "HIGH",IF( 'Compound Alert'!T174 >= 5, "MED","LOW")), IF( $B$8="Underlying Vulnerability", IF( 'Compound Alert'!AA174 >= 10, "HIGH",IF( 'Compound Alert'!AA174 >= 7, "MED","LOW")),IF( $B$8="Emerging Threat", IF( 'Compound Alert'!AH174 >= 10, "HIGH",IF( 'Compound Alert'!AH174 >= 7, "MED","LOW"))))) -> MED | M44: =IF( $B$8="Overall Alert",IF( 'Compound Alert'!U174 >= 7, "HIGH",IF( 'Compound Alert'!U174 >= 5, "MED","LOW")), IF( $B$8="Underlying Vulnerability", IF( 'Compound Alert'!AB174 >= 10, "HIGH",IF( 'Compound Alert'!AB174 >= 7, "MED","LOW")),IF( $B$8="Emerging Threat", IF( 'Compound Alert'!AI174 >= 10, "HIGH",IF( 'Compound Alert'!AI174 >= 7, "MED","LOW"))))) -> LOW | N44: =IF( $B$8="Overall Alert",IF( 'Compound Alert'!V174 >= 7, "HIGH",IF( 'Compound Alert'!V174 >= 5, "MED","LOW")), IF( $B$8="Underlying Vulnerability", IF( 'Compound Alert'!AC174 >= 10, "HIGH",IF( 'Compound Alert'!AC174 >= 7, "MED","LOW")),IF( $B$8="Emerging Threat", IF( 'Compound Alert'!AJ174 >= 10, "HIGH",IF( 'Compound Alert'!AJ174 >= 7, "MED","LOW"))))) -> LOW | O44: =IF( $B$8="Overall Alert",IF( 'Compound Alert'!W174 >= 7, "HIGH",IF( 'Compound Alert'!W174 >= 5, "MED","LOW")), IF( $B$8="Underlying Vulnerability", IF( 'Compound Alert'!AD174 >= 10, "HIGH",IF( 'Compound Alert'!AD174 >= 7, "MED","LOW")),IF( $B$8="Emerging Threat", IF( 'Compound Alert'!AK174 >= 10, "HIGH",IF( 'Compound Alert'!AK174 >= 7, "MED","LOW"))))) -> LOW
A45: 4 | B45: ='Compound Alert'!B136 -> Myanmar | C45: ='Compound Alert'!C136 -> MMR | D45: ='Compound Alert'!D136 -> EAS East Asia & Pacific | E45: ='Compound Alert'!E136 -> IDA | F45: ='Compound Alert'!F136 -> 131 | G45: =IF($B$8="Overall Alert",'Compound Alert'!G136,IF($B$8="Underlying Vulnerability",'Compound Alert'!J136,IF($B$8="Emerging Threat",'Compound Alert'!M136))) -> 2.5 | H45: =IF($B$8="Overall Alert",'Compound Alert'!H136,IF($B$8="Underlying Vulnerability",'Compound Alert'!K136,IF($B$8="Emerging Threat",'Compound Alert'!N136))) -> 2.5 | I45: =ROUNDDOWN(G45,0) -> 2 | J45: =IF( $B$8="Overall Alert",IF( 'Compound Alert'!R136 >= 7, "HIGH",IF( 'Compound Alert'!R136 >= 5, "MED","LOW")), IF( $B$8="Underlying Vulnerability", IF( 'Compound Alert'!Y136 >= 10, "HIGH",IF( 'Compound Alert'!Y136 >= 7, "MED","LOW")),IF( $B$8="Emerging Threat", IF( 'Compound Alert'!AF136 >= 10, "HIGH",IF( 'Compound Alert'!AF136 >= 7, "MED","LOW"))))) -> LOW | K45: =IF( $B$8="Overall Alert",IF( 'Compound Alert'!S136 >= 7, "HIGH",IF( 'Compound Alert'!S136 >= 5, "MED","LOW")), IF( $B$8="Underlying Vulnerability", IF( 'Compound Alert'!Z136 >= 10, "HIGH",IF( 'Compound Alert'!Z136 >= 7, "MED","LOW")),IF( $B$8="Emerging Threat", IF( 'Compound Alert'!AG136 >= 10, "HIGH",IF( 'Compound Alert'!AG136 >= 7, "MED","LOW"))))) -> LOW | L45: =IF( $B$8="Overall Alert",IF( 'Compound Alert'!T136 >= 7, "HIGH",IF( 'Compound Alert'!T136 >= 5, "MED","LOW")), IF( $B$8="Underlying Vulnerability", IF( 'Compound Alert'!AA136 >= 10, "HIGH",IF( 'Compound Alert'!AA136 >= 7, "MED","LOW")),IF( $B$8="Emerging Threat", IF( 'Compound Alert'!AH136 >= 10, "HIGH",IF( 'Compound Alert'!AH136 >= 7, "MED","LOW"))))) -> MED | M45: =IF( $B$8="Overall Alert",IF( 'Compound Alert'!U136 >= 7, "HIGH",IF( 'Compound Alert'!U136 >= 5, "MED","LOW")), IF( $B$8="Underlying Vulnerability", IF( 'Compound Alert'!AB136 >= 10, "HIGH",IF( 'Compound Alert'!AB136 >= 7, "MED","LOW")),IF( $B$8="Emerging Threat", IF( 'Compound Alert'!AI136 >= 10, "HIGH",IF( 'Compound Alert'!AI136 >= 7, "MED","LOW"))))) -> HIGH | N45: =IF( $B$8="Overall Alert",IF( 'Compound Alert'!V136 >= 7, "HIGH",IF( 'Compound Alert'!V136 >= 5, "MED","LOW")), IF( $B$8="Underlying Vulnerability", IF( 'Compound Alert'!AC136 >= 10, "HIGH",IF( 'Compound Alert'!AC136 >= 7, "MED","LOW")),IF( $B$8="Emerging Threat", IF( 'Compound Alert'!AJ136 >= 10, "HIGH",IF( 'Compound Alert'!AJ136 >= 7, "MED","LOW"))))) -> HIGH | O45: =IF( $B$8="Overall Alert",IF( 'Compound Alert'!W136 >= 7, "HIGH",IF( 'Compound Alert'!W136 >= 5, "MED","LOW")), IF( $B$8="Underlying Vulnerability", IF( 'Compound Alert'!AD136 >= 10, "HIGH",IF( 'Compound Alert'!AD136 >= 7, "MED","LOW")),IF( $B$8="Emerging Threat", IF( 'Compound Alert'!AK136 >= 10, "HIGH",IF( 'Compound Alert'!AK136 >= 7, "MED","LOW"))))) -> LOW
A46: 5 | B46: ='Compound Alert'!B148 -> Nigeria | C46: ='Compound Alert'!C148 -> NGA | D46: ='Compound Alert'!D148 -> SSF Sub-Saharan Africa | E46: ='Compound Alert'!E148 -> Blend | F46: ='Compound Alert'!F148 -> 143 | G46: =IF($B$8="Overall Alert",'Compound Alert'!G148,IF($B$8="Underlying Vulnerability",'Compound Alert'!J148,IF($B$8="Emerging Threat",'Compound Alert'!M148))) -> 2 | H46: =IF($B$8="Overall Alert",'Compound Alert'!H148,IF($B$8="Underlying Vulnerability",'Compound Alert'!K148,IF($B$8="Emerging Threat",'Compound Alert'!N148))) -> 2 | I46: =ROUNDDOWN(G46,0) -> 2 | J46: =IF( $B$8="Overall Alert",IF( 'Compound Alert'!R148 >= 7, "HIGH",IF( 'Compound Alert'!R148 >= 5, "MED","LOW")), IF( $B$8="Underlying Vulnerability", IF( 'Compound Alert'!Y148 >= 10, "HIGH",IF( 'Compound Alert'!Y148 >= 7, "MED","LOW")),IF( $B$8="Emerging Threat", IF( 'Compound Alert'!AF148 >= 10, "HIGH",IF( 'Compound Alert'!AF148 >= 7, "MED","LOW"))))) -> LOW | K46: =IF( $B$8="Overall Alert",IF( 'Compound Alert'!S148 >= 7, "HIGH",IF( 'Compound Alert'!S148 >= 5, "MED","LOW")), IF( $B$8="Underlying Vulnerability", IF( 'Compound Alert'!Z148 >= 10, "HIGH",IF( 'Compound Alert'!Z148 >= 7, "MED","LOW")),IF( $B$8="Emerging Threat", IF( 'Compound Alert'!AG148 >= 10, "HIGH",IF( 'Compound Alert'!AG148 >= 7, "MED","LOW"))))) -> HIGH | L46: =IF( $B$8="Overall Alert",IF( 'Compound Alert'!T148 >= 7, "HIGH",IF( 'Compound Alert'!T148 >= 5, "MED","LOW")), IF( $B$8="Underlying Vulnerability", IF( 'Compound Alert'!AA148 >= 10, "HIGH",IF( 'Compound Alert'!AA148 >= 7, "MED","LOW")),IF( $B$8="Emerging Threat", IF( 'Compound Alert'!AH148 >= 10, "HIGH",IF( 'Compound Alert'!AH148 >= 7, "MED","LOW"))))) -> LOW | M46: =IF( $B$8="Overall Alert",IF( 'Compound Alert'!U148 >= 7, "HIGH",IF( 'Compound Alert'!U148 >= 5, "MED","LOW")), IF( $B$8="Underlying Vulnerability", IF( 'Compound Alert'!AB148 >= 10, "HIGH",IF( 'Compound Alert'!AB148 >= 7, "MED","LOW")),IF( $B$8="Emerging Threat", IF( 'Compound Alert'!AI148 >= 10, "HIGH",IF( 'Compound Alert'!AI148 >= 7, "MED","LOW"))))) -> LOW | N46: =IF( $B$8="Overall Alert",IF( 'Compound Alert'!V148 >= 7, "HIGH",IF( 'Compound Alert'!V148 >= 5, "MED","LOW")), IF( $B$8="Underlying Vulnerability", IF( 'Compound Alert'!AC148 >= 10, "HIGH",IF( 'Compound Alert'!AC148 >= 7, "MED","LOW")),IF( $B$8="Emerging Threat", IF( 'Compound Alert'!AJ148 >= 10, "HIGH",IF( 'Compound Alert'!AJ148 >= 7, "MED","LOW"))))) -> LOW | O46: =IF( $B$8="Overall Alert",IF( 'Compound Alert'!W148 >= 7, "HIGH",IF( 'Compound Alert'!W148 >= 5, "MED","LOW")), IF( $B$8="Underlying Vulnerability", IF( 'Compound Alert'!AD148 >= 10, "HIGH",IF( 'Compound Alert'!AD148 >= 7, "MED","LOW")),IF( $B$8="Emerging Threat", IF( 'Compound Alert'!AK148 >= 10, "HIGH",IF( 'Compound Alert'!AK148 >= 7, "MED","LOW"))))) -> HIGH
A47: 6 | B47: ='Compound Alert'!B134 -> Mali | C47: ='Compound Alert'!C134 -> MLI | D47: ='Compound Alert'!D134 -> SSF Sub-Saharan Africa | E47: ='Compound Alert'!E134 -> IDA | F47: ='Compound Alert'!F134 -> 129 | G47: =IF($B$8="Overall Alert",'Compound Alert'!G134,IF($B$8="Underlying Vulnerability",'Compound Alert'!J134,IF($B$8="Emerging Threat",'Compound Alert'!M134))) -> 3 | H47: =IF($B$8="Overall Alert",'Compound Alert'!H134,IF($B$8="Underlying Vulnerability",'Compound Alert'!K134,IF($B$8="Emerging Threat",'Compound Alert'!N134))) -> 3 | I47: =ROUNDDOWN(G47,0) -> 3 | J47: =IF( $B$8="Overall Alert",IF( 'Compound Alert'!R134 >= 7, "HIGH",IF( 'Compound Alert'!R134 >= 5, "MED","LOW")), IF( $B$8="Underlying Vulnerability", IF( 'Compound Alert'!Y134 >= 10, "HIGH",IF( 'Compound Alert'!Y134 >= 7, "MED","LOW")),IF( $B$8="Emerging Threat", IF( 'Compound Alert'!AF134 >= 10, "HIGH",IF( 'Compound Alert'!AF134 >= 7, "MED","LOW"))))) -> LOW | K47: =IF( $B$8="Overall Alert",IF( 'Compound Alert'!S134 >= 7, "HIGH",IF( 'Compound Alert'!S134 >= 5, "MED","LOW")), IF( $B$8="Underlying Vulnerability", IF( 'Compound Alert'!Z134 >= 10, "HIGH",IF( 'Compound Alert'!Z134 >= 7, "MED","LOW")),IF( $B$8="Emerging Threat", IF( 'Compound Alert'!AG134 >= 10, "HIGH",IF( 'Compound Alert'!AG134 >= 7, "MED","LOW"))))) -> HIGH | L47: =IF( $B$8="Overall Alert",IF( 'Compound Alert'!T134 >= 7, "HIGH",IF( 'Compound Alert'!T134 >= 5, "MED","LOW")), IF( $B$8="Underlying Vulnerability", IF( 'Compound Alert'!AA134 >= 10, "HIGH",IF( 'Compound Alert'!AA134 >= 7, "MED","LOW")),IF( $B$8="Emerging Threat", IF( 'Compound Alert'!AH134 >= 10, "HIGH",IF( 'Compound Alert'!AH134 >= 7, "MED","LOW"))))) -> LOW | M47: =IF( $B$8="Overall Alert",IF( 'Compound Alert'!U134 >= 7, "HIGH",IF( 'Compound Alert'!U134 >= 5, "MED","LOW")), IF( $B$8="Underlying Vulnerability", IF( 'Compound Alert'!AB134 >= 10, "HIGH",IF( 'Compound Alert'!AB134 >= 7, "MED","LOW")),IF( $B$8="Emerging Threat", IF( 'Compound Alert'!AI134 >= 10, "HIGH",IF( 'Compound Alert'!AI134 >= 7, "MED","LOW"))))) -> LOW | N47: =IF( $B$8="Overall Alert",IF( 'Compound Alert'!V134 >= 7, "HIGH",IF( 'Compound Alert'!V134 >= 5, "MED","LOW")), IF( $B$8="Underlying Vulnerability", IF( 'Compound Alert'!AC134 >= 10, "HIGH",IF( 'Compound Alert'!AC134 >= 7, "MED","LOW")),IF( $B$8="Emerging Threat", IF( 'Compound Alert'!AJ134 >= 10, "HIGH",IF( 'Compound Alert'!AJ134 >= 7, "MED","LOW"))))) -> HIGH | O47: =IF( $B$8="Overall Alert",IF( 'Compound Alert'!W134 >= 7, "HIGH",IF( 'Compound Alert'!W134 >= 5, "MED","LOW")), IF( $B$8="Underlying Vulnerability", IF( 'Compound Alert'!AD134 >= 10, "HIGH",IF( 'Compound Alert'!AD134 >= 7, "MED","LOW")),IF( $B$8="Emerging Threat", IF( 'Compound Alert'!AK134 >= 10, "HIGH",IF( 'Compound Alert'!AK134 >= 7, "MED","LOW"))))) -> HIGH
A48: 7 | B48: ='Compound Alert'!B147 -> Niger | C48: ='Compound Alert'!C147 -> NER | D48: ='Compound Alert'!D147 -> SSF Sub-Saharan Africa | E48: ='Compound Alert'!E147 -> IDA | F48: ='Compound Alert'!F147 -> 142 | G48: =IF($B$8="Overall Alert",'Compound Alert'!G147,IF($B$8="Underlying Vulnerability",'Compound Alert'!J147,IF($B$8="Emerging Threat",'Compound Alert'!M147))) -> 2.5 | H48: =IF($B$8="Overall Alert",'Compound Alert'!H147,IF($B$8="Underlying Vulnerability",'Compound Alert'!K147,IF($B$8="Emerging Threat",'Compound Alert'!N147))) -> 2.5 | I48: =ROUNDDOWN(G48,0) -> 2 | J48: =IF( $B$8="Overall Alert",IF( 'Compound Alert'!R147 >= 7, "HIGH",IF( 'Compound Alert'!R147 >= 5, "MED","LOW")), IF( $B$8="Underlying Vulnerability", IF( 'Compound Alert'!Y147 >= 10, "HIGH",IF( 'Compound Alert'!Y147 >= 7, "MED","LOW")),IF( $B$8="Emerging Threat", IF( 'Compound Alert'!AF147 >= 10, "HIGH",IF( 'Compound Alert'!AF147 >= 7, "MED","LOW"))))) -> LOW | K48: =IF( $B$8="Overall Alert",IF( 'Compound Alert'!S147 >= 7, "HIGH",IF( 'Compound Alert'!S147 >= 5, "MED","LOW")), IF( $B$8="Underlying Vulnerability", IF( 'Compound Alert'!Z147 >= 10, "HIGH",IF( 'Compound Alert'!Z147 >= 7, "MED","LOW")),IF( $B$8="Emerging Threat", IF( 'Compound Alert'!AG147 >= 10, "HIGH",IF( 'Compound Alert'!AG147 >= 7, "MED","LOW"))))) -> HIGH | L48: =IF( $B$8="Overall Alert",IF( 'Compound Alert'!T147 >= 7, "HIGH",IF( 'Compound Alert'!T147 >= 5, "MED","LOW")), IF( $B$8="Underlying Vulnerability", IF( 'Compound Alert'!AA147 >= 10, "HIGH",IF( 'Compound Alert'!AA147 >= 7, "MED","LOW")),IF( $B$8="Emerging Threat", IF( 'Compound Alert'!AH147 >= 10, "HIGH",IF( 'Compound Alert'!AH147 >= 7, "MED","LOW"))))) -> LOW | M48: =IF( $B$8="Overall Alert",IF( 'Compound Alert'!U147 >= 7, "HIGH",IF( 'Compound Alert'!U147 >= 5, "MED","LOW")), IF( $B$8="Underlying Vulnerability", IF( 'Compound Alert'!AB147 >= 10, "HIGH",IF( 'Compound Alert'!AB147 >= 7, "MED","LOW")),IF( $B$8="Emerging Threat", IF( 'Compound Alert'!AI147 >= 10, "HIGH",IF( 'Compound Alert'!AI147 >= 7, "MED","LOW"))))) -> LOW | N48: =IF( $B$8="Overall Alert",IF( 'Compound Alert'!V147 >= 7, "HIGH",IF( 'Compound Alert'!V147 >= 5, "MED","LOW")), IF( $B$8="Underlying Vulnerability", IF( 'Compound Alert'!AC147 >= 10, "HIGH",IF( 'Compound Alert'!AC147 >= 7, "MED","LOW")),IF( $B$8="Emerging Threat", IF( 'Compound Alert'!AJ147 >= 10, "HIGH",IF( 'Compound Alert'!AJ147 >= 7, "MED","LOW"))))) -> MED | O48: =IF( $B$8="Overall Alert",IF( 'Compound Alert'!W147 >= 7, "HIGH",IF( 'Compound Alert'!W147 >= 5, "MED","LOW")), IF( $B$8="Underlying Vulnerability", IF( 'Compound Alert'!AD147 >= 10, "HIGH",IF( 'Compound Alert'!AD147 >= 7, "MED","LOW")),IF( $B$8="Emerging Threat", IF( 'Compound Alert'!AK147 >= 10, "HIGH",IF( 'Compound Alert'!AK147 >= 7, "MED","LOW"))))) -> HIGH
A49: 8 | B49: ='Compound Alert'!B156 -> Pakistan | C49: ='Compound Alert'!C156 -> PAK | D49: ='Compound Alert'!D156 -> SAS South Asia | E49: ='Compound Alert'!E156 -> Blend | F49: ='Compound Alert'!F156 -> 151 | G49: =IF($B$8="Overall Alert",'Compound Alert'!G156,IF($B$8="Underlying Vulnerability",'Compound Alert'!J156,IF($B$8="Emerging Threat",'Compound Alert'!M156))) -> 4 | H49: =IF($B$8="Overall Alert",'Compound Alert'!H156,IF($B$8="Underlying Vulnerability",'Compound Alert'!K156,IF($B$8="Emerging Threat",'Compound Alert'!N156))) -> 4 | I49: =ROUNDDOWN(G49,0) -> 4 | J49: =IF( $B$8="Overall Alert",IF( 'Compound Alert'!R156 >= 7, "HIGH",IF( 'Compound Alert'!R156 >= 5, "MED","LOW")), IF( $B$8="Underlying Vulnerability", IF( 'Compound Alert'!Y156 >= 10, "HIGH",IF( 'Compound Alert'!Y156 >= 7, "MED","LOW")),IF( $B$8="Emerging Threat", IF( 'Compound Alert'!AF156 >= 10, "HIGH",IF( 'Compound Alert'!AF156 >= 7, "MED","LOW"))))) -> LOW | K49: =IF( $B$8="Overall Alert",IF( 'Compound Alert'!S156 >= 7, "HIGH",IF( 'Compound Alert'!S156 >= 5, "MED","LOW")), IF( $B$8="Underlying Vulnerability", IF( 'Compound Alert'!Z156 >= 10, "HIGH",IF( 'Compound Alert'!Z156 >= 7, "MED","LOW")),IF( $B$8="Emerging Threat", IF( 'Compound Alert'!AG156 >= 10, "HIGH",IF( 'Compound Alert'!AG156 >= 7, "MED","LOW"))))) -> HIGH | L49: =IF( $B$8="Overall Alert",IF( 'Compound Alert'!T156 >= 7, "HIGH",IF( 'Compound Alert'!T156 >= 5, "MED","LOW")), IF( $B$8="Underlying Vulnerability", IF( 'Compound Alert'!AA156 >= 10, "HIGH",IF( 'Compound Alert'!AA156 >= 7, "MED","LOW")),IF( $B$8="Emerging Threat", IF( 'Compound Alert'!AH156 >= 10, "HIGH",IF( 'Compound Alert'!AH156 >= 7, "MED","LOW"))))) -> LOW | M49: =IF( $B$8="Overall Alert",IF( 'Compound Alert'!U156 >= 7, "HIGH",IF( 'Compound Alert'!U156 >= 5, "MED","LOW")), IF( $B$8="Underlying Vulnerability", IF( 'Compound Alert'!AB156 >= 10, "HIGH",IF( 'Compound Alert'!AB156 >= 7, "MED","LOW")),IF( $B$8="Emerging Threat", IF( 'Compound Alert'!AI156 >= 10, "HIGH",IF( 'Compound Alert'!AI156 >= 7, "MED","LOW"))))) -> HIGH | N49: =IF( $B$8="Overall Alert",IF( 'Compound Alert'!V156 >= 7, "HIGH",IF( 'Compound Alert'!V156 >= 5, "MED","LOW")), IF( $B$8="Underlying Vulnerability", IF( 'Compound Alert'!AC156 >= 10, "HIGH",IF( 'Compound Alert'!AC156 >= 7, "MED","LOW")),IF( $B$8="Emerging Threat", IF( 'Compound Alert'!AJ156 >= 10, "HIGH",IF( 'Compound Alert'!AJ156 >= 7, "MED","LOW"))))) -> HIGH | O49: =IF( $B$8="Overall Alert",IF( 'Compound Alert'!W156 >= 7, "HIGH",IF( 'Compound Alert'!W156 >= 5, "MED","LOW")), IF( $B$8="Underlying Vulnerability", IF( 'Compound Alert'!AD156 >= 10, "HIGH",IF( 'Compound Alert'!AD156 >= 7, "MED","LOW")),IF( $B$8="Emerging Threat", IF( 'Compound Alert'!AK156 >= 10, "HIGH",IF( 'Compound Alert'!AK156 >= 7, "MED","LOW"))))) -> HIGH
A50: 9 | B50: ='Compound Alert'!B192 -> Syrian Arab Republic | C50: ='Compound Alert'!C192 -> SYR | D50: ='Compound Alert'!D192 -> MEA Middle East & North Africa | E50: ='Compound Alert'!E192 -> IDA | F50: ='Compound Alert'!F192 -> 187 | G50: =IF($B$8="Overall Alert",'Compound Alert'!G192,IF($B$8="Underlying Vulnerability",'Compound Alert'!J192,IF($B$8="Emerging Threat",'Compound Alert'!M192))) -> 3 | H50: =IF($B$8="Overall Alert",'Compound Alert'!H192,IF($B$8="Underlying Vulnerability",'Compound Alert'!K192,IF($B$8="Emerging Threat",'Compound Alert'!N192))) -> 3 | I50: =ROUNDDOWN(G50,0) -> 3 | J50: =IF( $B$8="Overall Alert",IF( 'Compound Alert'!R192 >= 7, "HIGH",IF( 'Compound Alert'!R192 >= 5, "MED","LOW")), IF( $B$8="Underlying Vulnerability", IF( 'Compound Alert'!Y192 >= 10, "HIGH",IF( 'Compound Alert'!Y192 >= 7, "MED","LOW")),IF( $B$8="Emerging Threat", IF( 'Compound Alert'!AF192 >= 10, "HIGH",IF( 'Compound Alert'!AF192 >= 7, "MED","LOW"))))) -> LOW | K50: =IF( $B$8="Overall Alert",IF( 'Compound Alert'!S192 >= 7, "HIGH",IF( 'Compound Alert'!S192 >= 5, "MED","LOW")), IF( $B$8="Underlying Vulnerability", IF( 'Compound Alert'!Z192 >= 10, "HIGH",IF( 'Compound Alert'!Z192 >= 7, "MED","LOW")),IF( $B$8="Emerging Threat", IF( 'Compound Alert'!AG192 >= 10, "HIGH",IF( 'Compound Alert'!AG192 >= 7, "MED","LOW"))))) -> HIGH | L50: =IF( $B$8="Overall Alert",IF( 'Compound Alert'!T192 >= 7, "HIGH",IF( 'Compound Alert'!T192 >= 5, "MED","LOW")), IF( $B$8="Underlying Vulnerability", IF( 'Compound Alert'!AA192 >= 10, "HIGH",IF( 'Compound Alert'!AA192 >= 7, "MED","LOW")),IF( $B$8="Emerging Threat", IF( 'Compound Alert'!AH192 >= 10, "HIGH",IF( 'Compound Alert'!AH192 >= 7, "MED","LOW"))))) -> LOW | M50: =IF( $B$8="Overall Alert",IF( 'Compound Alert'!U192 >= 7, "HIGH",IF( 'Compound Alert'!U192 >= 5, "MED","LOW")), IF( $B$8="Underlying Vulnerability", IF( 'Compound Alert'!AB192 >= 10, "HIGH",IF( 'Compound Alert'!AB192 >= 7, "MED","LOW")),IF( $B$8="Emerging Threat", IF( 'Compound Alert'!AI192 >= 10, "HIGH",IF( 'Compound Alert'!AI192 >= 7, "MED","LOW"))))) -> HIGH | N50: =IF( $B$8="Overall Alert",IF( 'Compound Alert'!V192 >= 7, "HIGH",IF( 'Compound Alert'!V192 >= 5, "MED","LOW")), IF( $B$8="Underlying Vulnerability", IF( 'Compound Alert'!AC192 >= 10, "HIGH",IF( 'Compound Alert'!AC192 >= 7, "MED","LOW")),IF( $B$8="Emerging Threat", IF( 'Compound Alert'!AJ192 >= 10, "HIGH",IF( 'Compound Alert'!AJ192 >= 7, "MED","LOW"))))) -> HIGH | O50: =IF( $B$8="Overall Alert",IF( 'Compound Alert'!W192 >= 7, "HIGH",IF( 'Compound Alert'!W192 >= 5, "MED","LOW")), IF( $B$8="Underlying Vulnerability", IF( 'Compound Alert'!AD192 >= 10, "HIGH",IF( 'Compound Alert'!AD192 >= 7, "MED","LOW")),IF( $B$8="Emerging Threat", IF( 'Compound Alert'!AK192 >= 10, "HIGH",IF( 'Compound Alert'!AK192 >= 7, "MED","LOW"))))) -> LOW
A51: 10 | B51: ='Compound Alert'!B8 -> Angola | C51: ='Compound Alert'!C8 -> AGO | D51: ='Compound Alert'!D8 -> SSF Sub-Saharan Africa | E51: ='Compound Alert'!E8 -> IBRD | F51: ='Compound Alert'!F8 -> 3 | G51: =IF($B$8="Overall Alert",'Compound Alert'!G8,IF($B$8="Underlying Vulnerability",'Compound Alert'!J8,IF($B$8="Emerging Threat",'Compound Alert'!M8))) -> 2 | H51: =IF($B$8="Overall Alert",'Compound Alert'!H8,IF($B$8="Underlying Vulnerability",'Compound Alert'!K8,IF($B$8="Emerging Threat",'Compound Alert'!N8))) -> 2 | I51: =ROUNDDOWN(G51,0) -> 2 | J51: =IF( $B$8="Overall Alert",IF( 'Compound Alert'!R8 >= 7, "HIGH",IF( 'Compound Alert'!R8 >= 5, "MED","LOW")), IF( $B$8="Underlying Vulnerability", IF( 'Compound Alert'!Y8 >= 10, "HIGH",IF( 'Compound Alert'!Y8 >= 7, "MED","LOW")),IF( $B$8="Emerging Threat", IF( 'Compound Alert'!AF8 >= 10, "HIGH",IF( 'Compound Alert'!AF8 >= 7, "MED","LOW"))))) -> LOW | K51: =IF( $B$8="Overall Alert",IF( 'Compound Alert'!S8 >= 7, "HIGH",IF( 'Compound Alert'!S8 >= 5, "MED","LOW")), IF( $B$8="Underlying Vulnerability", IF( 'Compound Alert'!Z8 >= 10, "HIGH",IF( 'Compound Alert'!Z8 >= 7, "MED","LOW")),IF( $B$8="Emerging Threat", IF( 'Compound Alert'!AG8 >= 10, "HIGH",IF( 'Compound Alert'!AG8 >= 7, "MED","LOW"))))) -> LOW | L51: =IF( $B$8="Overall Alert",IF( 'Compound Alert'!T8 >= 7, "HIGH",IF( 'Compound Alert'!T8 >= 5, "MED","LOW")), IF( $B$8="Underlying Vulnerability", IF( 'Compound Alert'!AA8 >= 10, "HIGH",IF( 'Compound Alert'!AA8 >= 7, "MED","LOW")),IF( $B$8="Emerging Threat", IF( 'Compound Alert'!AH8 >= 10, "HIGH",IF( 'Compound Alert'!AH8 >= 7, "MED","LOW"))))) -> MED | M51: =IF( $B$8="Overall Alert",IF( 'Compound Alert'!U8 >= 7, "HIGH",IF( 'Compound Alert'!U8 >= 5, "MED","LOW")), IF( $B$8="Underlying Vulnerability", IF( 'Compound Alert'!AB8 >= 10, "HIGH",IF( 'Compound Alert'!AB8 >= 7, "MED","LOW")),IF( $B$8="Emerging Threat", IF( 'Compound Alert'!AI8 >= 10, "HIGH",IF( 'Compound Alert'!AI8 >= 7, "MED","LOW"))))) -> HIGH | N51: =IF( $B$8="Overall Alert",IF( 'Compound Alert'!V8 >= 7, "HIGH",IF( 'Compound Alert'!V8 >= 5, "MED","LOW")), IF( $B$8="Underlying Vulnerability", IF( 'Compound Alert'!AC8 >= 10, "HIGH",IF( 'Compound Alert'!AC8 >= 7, "MED","LOW")),IF( $B$8="Emerging Threat", IF( 'Compound Alert'!AJ8 >= 10, "HIGH",IF( 'Compound Alert'!AJ8 >= 7, "MED","LOW"))))) -> MED | O51: =IF( $B$8="Overall Alert",IF( 'Compound Alert'!W8 >= 7, "HIGH",IF( 'Compound Alert'!W8 >= 5, "MED","LOW")), IF( $B$8="Underlying Vulnerability", IF( 'Compound Alert'!AD8 >= 10, "HIGH",IF( 'Compound Alert'!AD8 >= 7, "MED","LOW")),IF( $B$8="Emerging Threat", IF( 'Compound Alert'!AK8 >= 10, "HIGH",IF( 'Compound Alert'!AK8 >= 7, "MED","LOW"))))) -> LOW
A52: 11 | B52: ='Compound Alert'!B91 -> Haiti | C52: ='Compound Alert'!C91 -> HTI | D52: ='Compound Alert'!D91 -> LCN Latin America & Caribbean | E52: ='Compound Alert'!E91 -> IDA | F52: ='Compound Alert'!F91 -> 86 | G52: =IF($B$8="Overall Alert",'Compound Alert'!G91,IF($B$8="Underlying Vulnerability",'Compound Alert'!J91,IF($B$8="Emerging Threat",'Compound Alert'!M91))) -> 3.5 | H52: =IF($B$8="Overall Alert",'Compound Alert'!H91,IF($B$8="Underlying Vulnerability",'Compound Alert'!K91,IF($B$8="Emerging Threat",'Compound Alert'!N91))) -> 3.5 | I52: =ROUNDDOWN(G52,0) -> 3 | J52: =IF( $B$8="Overall Alert",IF( 'Compound Alert'!R91 >= 7, "HIGH",IF( 'Compound Alert'!R91 >= 5, "MED","LOW")), IF( $B$8="Underlying Vulnerability", IF( 'Compound Alert'!Y91 >= 10, "HIGH",IF( 'Compound Alert'!Y91 >= 7, "MED","LOW")),IF( $B$8="Emerging Threat", IF( 'Compound Alert'!AF91 >= 10, "HIGH",IF( 'Compound Alert'!AF91 >= 7, "MED","LOW"))))) -> LOW | K52: =IF( $B$8="Overall Alert",IF( 'Compound Alert'!S91 >= 7, "HIGH",IF( 'Compound Alert'!S91 >= 5, "MED","LOW")), IF( $B$8="Underlying Vulnerability", IF( 'Compound Alert'!Z91 >= 10, "HIGH",IF( 'Compound Alert'!Z91 >= 7, "MED","LOW")),IF( $B$8="Emerging Threat", IF( 'Compound Alert'!AG91 >= 10, "HIGH",IF( 'Compound Alert'!AG91 >= 7, "MED","LOW"))))) -> HIGH | L52: =IF( $B$8="Overall Alert",IF( 'Compound Alert'!T91 >= 7, "HIGH",IF( 'Compound Alert'!T91 >= 5, "MED","LOW")), IF( $B$8="Underlying Vulnerability", IF( 'Compound Alert'!AA91 >= 10, "HIGH",IF( 'Compound Alert'!AA91 >= 7, "MED","LOW")),IF( $B$8="Emerging Threat", IF( 'Compound Alert'!AH91 >= 10, "HIGH",IF( 'Compound Alert'!AH91 >= 7, "MED","LOW"))))) -> MED | M52: =IF( $B$8="Overall Alert",IF( 'Compound Alert'!U91 >= 7, "HIGH",IF( 'Compound Alert'!U91 >= 5, "MED","LOW")), IF( $B$8="Underlying Vulnerability", IF( 'Compound Alert'!AB91 >= 10, "HIGH",IF( 'Compound Alert'!AB91 >= 7, "MED","LOW")),IF( $B$8="Emerging Threat", IF( 'Compound Alert'!AI91 >= 10, "HIGH",IF( 'Compound Alert'!AI91 >= 7, "MED","LOW"))))) -> HIGH | N52: =IF( $B$8="Overall Alert",IF( 'Compound Alert'!V91 >= 7, "HIGH",IF( 'Compound Alert'!V91 >= 5, "MED","LOW")), IF( $B$8="Underlying Vulnerability", IF( 'Compound Alert'!AC91 >= 10, "HIGH",IF( 'Compound Alert'!AC91 >= 7, "MED","LOW")),IF( $B$8="Emerging Threat", IF( 'Compound Alert'!AJ91 >= 10, "HIGH",IF( 'Compound Alert'!AJ91 >= 7, "MED","LOW"))))) -> HIGH | O52: =IF( $B$8="Overall Alert",IF( 'Compound Alert'!W91 >= 7, "HIGH",IF( 'Compound Alert'!W91 >= 5, "MED","LOW")), IF( $B$8="Underlying Vulnerability", IF( 'Compound Alert'!AD91 >= 10, "HIGH",IF( 'Compound Alert'!AD91 >= 7, "MED","LOW")),IF( $B$8="Emerging Threat", IF( 'Compound Alert'!AK91 >= 10, "HIGH",IF( 'Compound Alert'!AK91 >= 7, "MED","LOW"))))) -> LOW
A53: 12 | B53: ='Compound Alert'!B22 -> Burkina Faso | C53: ='Compound Alert'!C22 -> BFA | D53: ='Compound Alert'!D22 -> SSF Sub-Saharan Africa | E53: ='Compound Alert'!E22 -> IDA | F53: ='Compound Alert'!F22 -> 17 | G53: =IF($B$8="Overall Alert",'Compound Alert'!G22,IF($B$8="Underlying Vulnerability",'Compound Alert'!J22,IF($B$8="Emerging Threat",'Compound Alert'!M22))) -> 2.5 | H53: =IF($B$8="Overall Alert",'Compound Alert'!H22,IF($B$8="Underlying Vulnerability",'Compound Alert'!K22,IF($B$8="Emerging Threat",'Compound Alert'!N22))) -> 2.5 | I53: =ROUNDDOWN(G53,0) -> 2 | J53: =IF( $B$8="Overall Alert",IF( 'Compound Alert'!R22 >= 7, "HIGH",IF( 'Compound Alert'!R22 >= 5, "MED","LOW")), IF( $B$8="Underlying Vulnerability", IF( 'Compound Alert'!Y22 >= 10, "HIGH",IF( 'Compound Alert'!Y22 >= 7, "MED","LOW")),IF( $B$8="Emerging Threat", IF( 'Compound Alert'!AF22 >= 10, "HIGH",IF( 'Compound Alert'!AF22 >= 7, "MED","LOW"))))) -> LOW | K53: =IF( $B$8="Overall Alert",IF( 'Compound Alert'!S22 >= 7, "HIGH",IF( 'Compound Alert'!S22 >= 5, "MED","LOW")), IF( $B$8="Underlying Vulnerability", IF( 'Compound Alert'!Z22 >= 10, "HIGH",IF( 'Compound Alert'!Z22 >= 7, "MED","LOW")),IF( $B$8="Emerging Threat", IF( 'Compound Alert'!AG22 >= 10, "HIGH",IF( 'Compound Alert'!AG22 >= 7, "MED","LOW"))))) -> HIGH | L53: =IF( $B$8="Overall Alert",IF( 'Compound Alert'!T22 >= 7, "HIGH",IF( 'Compound Alert'!T22 >= 5, "MED","LOW")), IF( $B$8="Underlying Vulnerability", IF( 'Compound Alert'!AA22 >= 10, "HIGH",IF( 'Compound Alert'!AA22 >= 7, "MED","LOW")),IF( $B$8="Emerging Threat", IF( 'Compound Alert'!AH22 >= 10, "HIGH",IF( 'Compound Alert'!AH22 >= 7, "MED","LOW"))))) -> LOW | M53: =IF( $B$8="Overall Alert",IF( 'Compound Alert'!U22 >= 7, "HIGH",IF( 'Compound Alert'!U22 >= 5, "MED","LOW")), IF( $B$8="Underlying Vulnerability", IF( 'Compound Alert'!AB22 >= 10, "HIGH",IF( 'Compound Alert'!AB22 >= 7, "MED","LOW")),IF( $B$8="Emerging Threat", IF( 'Compound Alert'!AI22 >= 10, "HIGH",IF( 'Compound Alert'!AI22 >= 7, "MED","LOW"))))) -> LOW | N53: =IF( $B$8="Overall Alert",IF( 'Compound Alert'!V22 >= 7, "HIGH",IF( 'Compound Alert'!V22 >= 5, "MED","LOW")), IF( $B$8="Underlying Vulnerability", IF( 'Compound Alert'!AC22 >= 10, "HIGH",IF( 'Compound Alert'!AC22 >= 7, "MED","LOW")),IF( $B$8="Emerging Threat", IF( 'Compound Alert'!AJ22 >= 10, "HIGH",IF( 'Compound Alert'!AJ22 >= 7, "MED","LOW"))))) -> MED | O53: =IF( $B$8="Overall Alert",IF( 'Compound Alert'!W22 >= 7, "HIGH",IF( 'Compound Alert'!W22 >= 5, "MED","LOW")), IF( $B$8="Underlying Vulnerability", IF( 'Compound Alert'!AD22 >= 10, "HIGH",IF( 'Compound Alert'!AD22 >= 7, "MED","LOW")),IF( $B$8="Emerging Threat", IF( 'Compound Alert'!AK22 >= 10, "HIGH",IF( 'Compound Alert'!AK22 >= 7, "MED","LOW"))))) -> HIGH
A54: 13 | B54: ='Compound Alert'!B143 -> Malawi | C54: ='Compound Alert'!C143 -> MWI | D54: ='Compound Alert'!D143 -> SSF Sub-Saharan Africa | E54: ='Compound Alert'!E143 -> IDA | F54: ='Compound Alert'!F143 -> 138 | G54: =IF($B$8="Overall Alert",'Compound Alert'!G143,IF($B$8="Underlying Vulnerability",'Compound Alert'!J143,IF($B$8="Emerging Threat",'Compound Alert'!M143))) -> 3 | H54: =IF($B$8="Overall Alert",'Compound Alert'!H143,IF($B$8="Underlying Vulnerability",'Compound Alert'!K143,IF($B$8="Emerging Threat",'Compound Alert'!N143))) -> 3 | I54: =ROUNDDOWN(G54,0) -> 3 | J54: =IF( $B$8="Overall Alert",IF( 'Compound Alert'!R143 >= 7, "HIGH",IF( 'Compound Alert'!R143 >= 5, "MED","LOW")), IF( $B$8="Underlying Vulnerability", IF( 'Compound Alert'!Y143 >= 10, "HIGH",IF( 'Compound Alert'!Y143 >= 7, "MED","LOW")),IF( $B$8="Emerging Threat", IF( 'Compound Alert'!AF143 >= 10, "HIGH",IF( 'Compound Alert'!AF143 >= 7, "MED","LOW"))))) -> HIGH | K54: =IF( $B$8="Overall Alert",IF( 'Compound Alert'!S143 >= 7, "HIGH",IF( 'Compound Alert'!S143 >= 5, "MED","LOW")), IF( $B$8="Underlying Vulnerability", IF( 'Compound Alert'!Z143 >= 10, "HIGH",IF( 'Compound Alert'!Z143 >= 7, "MED","LOW")),IF( $B$8="Emerging Threat", IF( 'Compound Alert'!AG143 >= 10, "HIGH",IF( 'Compound Alert'!AG143 >= 7, "MED","LOW"))))) -> MED | L54: =IF( $B$8="Overall Alert",IF( 'Compound Alert'!T143 >= 7, "HIGH",IF( 'Compound Alert'!T143 >= 5, "MED","LOW")), IF( $B$8="Underlying Vulnerability", IF( 'Compound Alert'!AA143 >= 10, "HIGH",IF( 'Compound Alert'!AA143 >= 7, "MED","LOW")),IF( $B$8="Emerging Threat", IF( 'Compound Alert'!AH143 >= 10, "HIGH",IF( 'Compound Alert'!AH143 >= 7, "MED","LOW"))))) -> MED | M54: =IF( $B$8="Overall Alert",IF( 'Compound Alert'!U143 >= 7, "HIGH",IF( 'Compound Alert'!U143 >= 5, "MED","LOW")), IF( $B$8="Underlying Vulnerability", IF( 'Compound Alert'!AB143 >= 10, "HIGH",IF( 'Compound Alert'!AB143 >= 7, "MED","LOW")),IF( $B$8="Emerging Threat", IF( 'Compound Alert'!AI143 >= 10, "HIGH",IF( 'Compound Alert'!AI143 >= 7, "MED","LOW"))))) -> MED | N54: =IF( $B$8="Overall Alert",IF( 'Compound Alert'!V143 >= 7, "HIGH",IF( 'Compound Alert'!V143 >= 5, "MED","LOW")), IF( $B$8="Underlying Vulnerability", IF( 'Compound Alert'!AC143 >= 10, "HIGH",IF( 'Compound Alert'!AC143 >= 7, "MED","LOW")),IF( $B$8="Emerging Threat", IF( 'Compound Alert'!AJ143 >= 10, "HIGH",IF( 'Compound Alert'!AJ143 >= 7, "MED","LOW"))))) -> MED | O54: =IF( $B$8="Overall Alert",IF( 'Compound Alert'!W143 >= 7, "HIGH",IF( 'Compound Alert'!W143 >= 5, "MED","LOW")), IF( $B$8="Underlying Vulnerability", IF( 'Compound Alert'!AD143 >= 10, "HIGH",IF( 'Compound Alert'!AD143 >= 7, "MED","LOW")),IF( $B$8="Emerging Threat", IF( 'Compound Alert'!AK143 >= 10, "HIGH",IF( 'Compound Alert'!AK143 >= 7, "MED","LOW"))))) -> LOW
A55: 14 | B55: ='Compound Alert'!B19 -> Burundi | C55: ='Compound Alert'!C19 -> BDI | D55: ='Compound Alert'!D19 -> SSF Sub-Saharan Africa | E55: ='Compound Alert'!E19 -> IDA | F55: ='Compound Alert'!F19 -> 14 | G55: =IF($B$8="Overall Alert",'Compound Alert'!G19,IF($B$8="Underlying Vulnerability",'Compound Alert'!J19,IF($B$8="Emerging Threat",'Compound Alert'!M19))) -> 2.5 | H55: =IF($B$8="Overall Alert",'Compound Alert'!H19,IF($B$8="Underlying Vulnerability",'Compound Alert'!K19,IF($B$8="Emerging Threat",'Compound Alert'!N19))) -> 2.5 | I55: =ROUNDDOWN(G55,0) -> 2 | J55: =IF( $B$8="Overall Alert",IF( 'Compound Alert'!R19 >= 7, "HIGH",IF( 'Compound Alert'!R19 >= 5, "MED","LOW")), IF( $B$8="Underlying Vulnerability", IF( 'Compound Alert'!Y19 >= 10, "HIGH",IF( 'Compound Alert'!Y19 >= 7, "MED","LOW")),IF( $B$8="Emerging Threat", IF( 'Compound Alert'!AF19 >= 10, "HIGH",IF( 'Compound Alert'!AF19 >= 7, "MED","LOW"))))) -> LOW | K55: =IF( $B$8="Overall Alert",IF( 'Compound Alert'!S19 >= 7, "HIGH",IF( 'Compound Alert'!S19 >= 5, "MED","LOW")), IF( $B$8="Underlying Vulnerability", IF( 'Compound Alert'!Z19 >= 10, "HIGH",IF( 'Compound Alert'!Z19 >= 7, "MED","LOW")),IF( $B$8="Emerging Threat", IF( 'Compound Alert'!AG19 >= 10, "HIGH",IF( 'Compound Alert'!AG19 >= 7, "MED","LOW"))))) -> HIGH | L55: =IF( $B$8="Overall Alert",IF( 'Compound Alert'!T19 >= 7, "HIGH",IF( 'Compound Alert'!T19 >= 5, "MED","LOW")), IF( $B$8="Underlying Vulnerability", IF( 'Compound Alert'!AA19 >= 10, "HIGH",IF( 'Compound Alert'!AA19 >= 7, "MED","LOW")),IF( $B$8="Emerging Threat", IF( 'Compound Alert'!AH19 >= 10, "HIGH",IF( 'Compound Alert'!AH19 >= 7, "MED","LOW"))))) -> MED | M55: =IF( $B$8="Overall Alert",IF( 'Compound Alert'!U19 >= 7, "HIGH",IF( 'Compound Alert'!U19 >= 5, "MED","LOW")), IF( $B$8="Underlying Vulnerability", IF( 'Compound Alert'!AB19 >= 10, "HIGH",IF( 'Compound Alert'!AB19 >= 7, "MED","LOW")),IF( $B$8="Emerging Threat", IF( 'Compound Alert'!AI19 >= 10, "HIGH",IF( 'Compound Alert'!AI19 >= 7, "MED","LOW"))))) -> LOW | N55: =IF( $B$8="Overall Alert",IF( 'Compound Alert'!V19 >= 7, "HIGH",IF( 'Compound Alert'!V19 >= 5, "MED","LOW")), IF( $B$8="Underlying Vulnerability", IF( 'Compound Alert'!AC19 >= 10, "HIGH",IF( 'Compound Alert'!AC19 >= 7, "MED","LOW")),IF( $B$8="Emerging Threat", IF( 'Compound Alert'!AJ19 >= 10, "HIGH",IF( 'Compound Alert'!AJ19 >= 7, "MED","LOW"))))) -> MED | O55: =IF( $B$8="Overall Alert",IF( 'Compound Alert'!W19 >= 7, "HIGH",IF( 'Compound Alert'!W19 >= 5, "MED","LOW")), IF( $B$8="Underlying Vulnerability", IF( 'Compound Alert'!AD19 >= 10, "HIGH",IF( 'Compound Alert'!AD19 >= 7, "MED","LOW")),IF( $B$8="Emerging Threat", IF( 'Compound Alert'!AK19 >= 10, "HIGH",IF( 'Compound Alert'!AK19 >= 7, "MED","LOW"))))) -> MED
A56: 15 | B56: ='Compound Alert'!B67 -> Ethiopia | C56: ='Compound Alert'!C67 -> ETH | D56: ='Compound Alert'!D67 -> SSF Sub-Saharan Africa | E56: ='Compound Alert'!E67 -> IDA | F56: ='Compound Alert'!F67 -> 62 | G56: =IF($B$8="Overall Alert",'Compound Alert'!G67,IF($B$8="Underlying Vulnerability",'Compound Alert'!J67,IF($B$8="Emerging Threat",'Compound Alert'!M67))) -> 2 | H56: =IF($B$8="Overall Alert",'Compound Alert'!H67,IF($B$8="Underlying Vulnerability",'Compound Alert'!K67,IF($B$8="Emerging Threat",'Compound Alert'!N67))) -> 2 | I56: =ROUNDDOWN(G56,0) -> 2 | J56: =IF( $B$8="Overall Alert",IF( 'Compound Alert'!R67 >= 7, "HIGH",IF( 'Compound Alert'!R67 >= 5, "MED","LOW")), IF( $B$8="Underlying Vulnerability", IF( 'Compound Alert'!Y67 >= 10, "HIGH",IF( 'Compound Alert'!Y67 >= 7, "MED","LOW")),IF( $B$8="Emerging Threat", IF( 'Compound Alert'!AF67 >= 10, "HIGH",IF( 'Compound Alert'!AF67 >= 7, "MED","LOW"))))) -> LOW | K56: =IF( $B$8="Overall Alert",IF( 'Compound Alert'!S67 >= 7, "HIGH",IF( 'Compound Alert'!S67 >= 5, "MED","LOW")), IF( $B$8="Underlying Vulnerability", IF( 'Compound Alert'!Z67 >= 10, "HIGH",IF( 'Compound Alert'!Z67 >= 7, "MED","LOW")),IF( $B$8="Emerging Threat", IF( 'Compound Alert'!AG67 >= 10, "HIGH",IF( 'Compound Alert'!AG67 >= 7, "MED","LOW"))))) -> HIGH | L56: =IF( $B$8="Overall Alert",IF( 'Compound Alert'!T67 >= 7, "HIGH",IF( 'Compound Alert'!T67 >= 5, "MED","LOW")), IF( $B$8="Underlying Vulnerability", IF( 'Compound Alert'!AA67 >= 10, "HIGH",IF( 'Compound Alert'!AA67 >= 7, "MED","LOW")),IF( $B$8="Emerging Threat", IF( 'Compound Alert'!AH67 >= 10, "HIGH",IF( 'Compound Alert'!AH67 >= 7, "MED","LOW"))))) -> LOW | M56: =IF( $B$8="Overall Alert",IF( 'Compound Alert'!U67 >= 7, "HIGH",IF( 'Compound Alert'!U67 >= 5, "MED","LOW")), IF( $B$8="Underlying Vulnerability", IF( 'Compound Alert'!AB67 >= 10, "HIGH",IF( 'Compound Alert'!AB67 >= 7, "MED","LOW")),IF( $B$8="Emerging Threat", IF( 'Compound Alert'!AI67 >= 10, "HIGH",IF( 'Compound Alert'!AI67 >= 7, "MED","LOW"))))) -> LOW | N56: =IF( $B$8="Overall Alert",IF( 'Compound Alert'!V67 >= 7, "HIGH",IF( 'Compound Alert'!V67 >= 5, "MED","LOW")), IF( $B$8="Underlying Vulnerability", IF( 'Compound Alert'!AC67 >= 10, "HIGH",IF( 'Compound Alert'!AC67 >= 7, "MED","LOW")),IF( $B$8="Emerging Threat", IF( 'Compound Alert'!AJ67 >= 10, "HIGH",IF( 'Compound Alert'!AJ67 >= 7, "MED","LOW"))))) -> MED | O56: =IF( $B$8="Overall Alert",IF( 'Compound Alert'!W67 >= 7, "HIGH",IF( 'Compound Alert'!W67 >= 5, "MED","LOW")), IF( $B$8="Underlying Vulnerability", IF( 'Compound Alert'!AD67 >= 10, "HIGH",IF( 'Compound Alert'!AD67 >= 7, "MED","LOW")),IF( $B$8="Emerging Threat", IF( 'Compound Alert'!AK67 >= 10, "HIGH",IF( 'Compound Alert'!AK67 >= 7, "MED","LOW"))))) -> MED
A57: 16 | B57: ='Compound Alert'!B220 -> Yemen, Rep. | C57: ='Compound Alert'!C220 -> YEM | D57: ='Compound Alert'!D220 -> MEA Middle East & North Africa | E57: ='Compound Alert'!E220 -> IDA | F57: ='Compound Alert'!F220 -> 0 | G57: =IF($B$8="Overall Alert",'Compound Alert'!G220,IF($B$8="Underlying Vulnerability",'Compound Alert'!J220,IF($B$8="Emerging Threat",'Compound Alert'!M220))) -> 5 | H57: =IF($B$8="Overall Alert",'Compound Alert'!H220,IF($B$8="Underlying Vulnerability",'Compound Alert'!K220,IF($B$8="Emerging Threat",'Compound Alert'!N220))) -> 5 | I57: =ROUNDDOWN(G57,0) -> 5 | J57: =IF( $B$8="Overall Alert",IF( 'Compound Alert'!R220 >= 7, "HIGH",IF( 'Compound Alert'!R220 >= 5, "MED","LOW")), IF( $B$8="Underlying Vulnerability", IF( 'Compound Alert'!Y220 >= 10, "HIGH",IF( 'Compound Alert'!Y220 >= 7, "MED","LOW")),IF( $B$8="Emerging Threat", IF( 'Compound Alert'!AF220 >= 10, "HIGH",IF( 'Compound Alert'!AF220 >= 7, "MED","LOW"))))) -> LOW | K57: =IF( $B$8="Overall Alert",IF( 'Compound Alert'!S220 >= 7, "HIGH",IF( 'Compound Alert'!S220 >= 5, "MED","LOW")), IF( $B$8="Underlying Vulnerability", IF( 'Compound Alert'!Z220 >= 10, "HIGH",IF( 'Compound Alert'!Z220 >= 7, "MED","LOW")),IF( $B$8="Emerging Threat", IF( 'Compound Alert'!AG220 >= 10, "HIGH",IF( 'Compound Alert'!AG220 >= 7, "MED","LOW"))))) -> HIGH | L57: =IF( $B$8="Overall Alert",IF( 'Compound Alert'!T220 >= 7, "HIGH",IF( 'Compound Alert'!T220 >= 5, "MED","LOW")), IF( $B$8="Underlying Vulnerability", IF( 'Compound Alert'!AA220 >= 10, "HIGH",IF( 'Compound Alert'!AA220 >= 7, "MED","LOW")),IF( $B$8="Emerging Threat", IF( 'Compound Alert'!AH220 >= 10, "HIGH",IF( 'Compound Alert'!AH220 >= 7, "MED","LOW"))))) -> HIGH | M57: =IF( $B$8="Overall Alert",IF( 'Compound Alert'!U220 >= 7, "HIGH",IF( 'Compound Alert'!U220 >= 5, "MED","LOW")), IF( $B$8="Underlying Vulnerability", IF( 'Compound Alert'!AB220 >= 10, "HIGH",IF( 'Compound Alert'!AB220 >= 7, "MED","LOW")),IF( $B$8="Emerging Threat", IF( 'Compound Alert'!AI220 >= 10, "HIGH",IF( 'Compound Alert'!AI220 >= 7, "MED","LOW"))))) -> HIGH | N57: =IF( $B$8="Overall Alert",IF( 'Compound Alert'!V220 >= 7, "HIGH",IF( 'Compound Alert'!V220 >= 5, "MED","LOW")), IF( $B$8="Underlying Vulnerability", IF( 'Compound Alert'!AC220 >= 10, "HIGH",IF( 'Compound Alert'!AC220 >= 7, "MED","LOW")),IF( $B$8="Emerging Threat", IF( 'Compound Alert'!AJ220 >= 10, "HIGH",IF( 'Compound Alert'!AJ220 >= 7, "MED","LOW"))))) -> HIGH | O57: =IF( $B$8="Overall Alert",IF( 'Compound Alert'!W220 >= 7, "HIGH",IF( 'Compound Alert'!W220 >= 5, "MED","LOW")), IF( $B$8="Underlying Vulnerability", IF( 'Compound Alert'!AD220 >= 10, "HIGH",IF( 'Compound Alert'!AD220 >= 7, "MED","LOW")),IF( $B$8="Emerging Threat", IF( 'Compound Alert'!AK220 >= 10, "HIGH",IF( 'Compound Alert'!AK220 >= 7, "MED","LOW"))))) -> HIGH
A58: 17 | B58: ='Compound Alert'!B45 -> Congo, Dem. Rep. | C58: ='Compound Alert'!C45 -> COD | D58: ='Compound Alert'!D45 -> SSF Sub-Saharan Africa | E58: ='Compound Alert'!E45 -> IDA | F58: ='Compound Alert'!F45 -> 40 | G58: =IF($B$8="Overall Alert",'Compound Alert'!G45,IF($B$8="Underlying Vulnerability",'Compound Alert'!J45,IF($B$8="Emerging Threat",'Compound Alert'!M45))) -> 3.5 | H58: =IF($B$8="Overall Alert",'Compound Alert'!H45,IF($B$8="Underlying Vulnerability",'Compound Alert'!K45,IF($B$8="Emerging Threat",'Compound Alert'!N45))) -> 3.5 | I58: =ROUNDDOWN(G58,0) -> 3 | J58: =IF( $B$8="Overall Alert",IF( 'Compound Alert'!R45 >= 7, "HIGH",IF( 'Compound Alert'!R45 >= 5, "MED","LOW")), IF( $B$8="Underlying Vulnerability", IF( 'Compound Alert'!Y45 >= 10, "HIGH",IF( 'Compound Alert'!Y45 >= 7, "MED","LOW")),IF( $B$8="Emerging Threat", IF( 'Compound Alert'!AF45 >= 10, "HIGH",IF( 'Compound Alert'!AF45 >= 7, "MED","LOW"))))) -> HIGH | K58: =IF( $B$8="Overall Alert",IF( 'Compound Alert'!S45 >= 7, "HIGH",IF( 'Compound Alert'!S45 >= 5, "MED","LOW")), IF( $B$8="Underlying Vulnerability", IF( 'Compound Alert'!Z45 >= 10, "HIGH",IF( 'Compound Alert'!Z45 >= 7, "MED","LOW")),IF( $B$8="Emerging Threat", IF( 'Compound Alert'!AG45 >= 10, "HIGH",IF( 'Compound Alert'!AG45 >= 7, "MED","LOW"))))) -> HIGH | L58: =IF( $B$8="Overall Alert",IF( 'Compound Alert'!T45 >= 7, "HIGH",IF( 'Compound Alert'!T45 >= 5, "MED","LOW")), IF( $B$8="Underlying Vulnerability", IF( 'Compound Alert'!AA45 >= 10, "HIGH",IF( 'Compound Alert'!AA45 >= 7, "MED","LOW")),IF( $B$8="Emerging Threat", IF( 'Compound Alert'!AH45 >= 10, "HIGH",IF( 'Compound Alert'!AH45 >= 7, "MED","LOW"))))) -> MED | M58: =IF( $B$8="Overall Alert",IF( 'Compound Alert'!U45 >= 7, "HIGH",IF( 'Compound Alert'!U45 >= 5, "MED","LOW")), IF( $B$8="Underlying Vulnerability", IF( 'Compound Alert'!AB45 >= 10, "HIGH",IF( 'Compound Alert'!AB45 >= 7, "MED","LOW")),IF( $B$8="Emerging Threat", IF( 'Compound Alert'!AI45 >= 10, "HIGH",IF( 'Compound Alert'!AI45 >= 7, "MED","LOW"))))) -> LOW | N58: =IF( $B$8="Overall Alert",IF( 'Compound Alert'!V45 >= 7, "HIGH",IF( 'Compound Alert'!V45 >= 5, "MED","LOW")), IF( $B$8="Underlying Vulnerability", IF( 'Compound Alert'!AC45 >= 10, "HIGH",IF( 'Compound Alert'!AC45 >= 7, "MED","LOW")),IF( $B$8="Emerging Threat", IF( 'Compound Alert'!AJ45 >= 10, "HIGH",IF( 'Compound Alert'!AJ45 >= 7, "MED","LOW"))))) -> HIGH | O58: =IF( $B$8="Overall Alert",IF( 'Compound Alert'!W45 >= 7, "HIGH",IF( 'Compound Alert'!W45 >= 5, "MED","LOW")), IF( $B$8="Underlying Vulnerability", IF( 'Compound Alert'!AD45 >= 10, "HIGH",IF( 'Compound Alert'!AD45 >= 7, "MED","LOW")),IF( $B$8="Emerging Threat", IF( 'Compound Alert'!AK45 >= 10, "HIGH",IF( 'Compound Alert'!AK45 >= 7, "MED","LOW"))))) -> LOW
A59: 18 | B59: ='Compound Alert'!B183 -> South Sudan | C59: ='Compound Alert'!C183 -> SSD | D59: ='Compound Alert'!D183 -> SSF Sub-Saharan Africa | E59: ='Compound Alert'!E183 -> IDA | F59: ='Compound Alert'!F183 -> 178 | G59: =IF($B$8="Overall Alert",'Compound Alert'!G183,IF($B$8="Underlying Vulnerability",'Compound Alert'!J183,IF($B$8="Emerging Threat",'Compound Alert'!M183))) -> 2 | H59: =IF($B$8="Overall Alert",'Compound Alert'!H183,IF($B$8="Underlying Vulnerability",'Compound Alert'!K183,IF($B$8="Emerging Threat",'Compound Alert'!N183))) -> 2 | I59: =ROUNDDOWN(G59,0) -> 2 | J59: =IF( $B$8="Overall Alert",IF( 'Compound Alert'!R183 >= 7, "HIGH",IF( 'Compound Alert'!R183 >= 5, "MED","LOW")), IF( $B$8="Underlying Vulnerability", IF( 'Compound Alert'!Y183 >= 10, "HIGH",IF( 'Compound Alert'!Y183 >= 7, "MED","LOW")),IF( $B$8="Emerging Threat", IF( 'Compound Alert'!AF183 >= 10, "HIGH",IF( 'Compound Alert'!AF183 >= 7, "MED","LOW"))))) -> LOW | K59: =IF( $B$8="Overall Alert",IF( 'Compound Alert'!S183 >= 7, "HIGH",IF( 'Compound Alert'!S183 >= 5, "MED","LOW")), IF( $B$8="Underlying Vulnerability", IF( 'Compound Alert'!Z183 >= 10, "HIGH",IF( 'Compound Alert'!Z183 >= 7, "MED","LOW")),IF( $B$8="Emerging Threat", IF( 'Compound Alert'!AG183 >= 10, "HIGH",IF( 'Compound Alert'!AG183 >= 7, "MED","LOW"))))) -> HIGH | L59: =IF( $B$8="Overall Alert",IF( 'Compound Alert'!T183 >= 7, "HIGH",IF( 'Compound Alert'!T183 >= 5, "MED","LOW")), IF( $B$8="Underlying Vulnerability", IF( 'Compound Alert'!AA183 >= 10, "HIGH",IF( 'Compound Alert'!AA183 >= 7, "MED","LOW")),IF( $B$8="Emerging Threat", IF( 'Compound Alert'!AH183 >= 10, "HIGH",IF( 'Compound Alert'!AH183 >= 7, "MED","LOW"))))) -> #N/A | M59: =IF( $B$8="Overall Alert",IF( 'Compound Alert'!U183 >= 7, "HIGH",IF( 'Compound Alert'!U183 >= 5, "MED","LOW")), IF( $B$8="Underlying Vulnerability", IF( 'Compound Alert'!AB183 >= 10, "HIGH",IF( 'Compound Alert'!AB183 >= 7, "MED","LOW")),IF( $B$8="Emerging Threat", IF( 'Compound Alert'!AI183 >= 10, "HIGH",IF( 'Compound Alert'!AI183 >= 7, "MED","LOW"))))) -> LOW | N59: =IF( $B$8="Overall Alert",IF( 'Compound Alert'!V183 >= 7, "HIGH",IF( 'Compound Alert'!V183 >= 5, "MED","LOW")), IF( $B$8="Underlying Vulnerability", IF( 'Compound Alert'!AC183 >= 10, "HIGH",IF( 'Compound Alert'!AC183 >= 7, "MED","LOW")),IF( $B$8="Emerging Threat", IF( 'Compound Alert'!AJ183 >= 10, "HIGH",IF( 'Compound Alert'!AJ183 >= 7, "MED","LOW"))))) -> MED | O59: =IF( $B$8="Overall Alert",IF( 'Compound Alert'!W183 >= 7, "HIGH",IF( 'Compound Alert'!W183 >= 5, "MED","LOW")), IF( $B$8="Underlying Vulnerability", IF( 'Compound Alert'!AD183 >= 10, "HIGH",IF( 'Compound Alert'!AD183 >= 7, "MED","LOW")),IF( $B$8="Emerging Threat", IF( 'Compound Alert'!AK183 >= 10, "HIGH",IF( 'Compound Alert'!AK183 >= 7, "MED","LOW"))))) -> MED
A60: 19 | B60: ='Compound Alert'!B207 -> Uganda | C60: ='Compound Alert'!C207 -> UGA | D60: ='Compound Alert'!D207 -> SSF Sub-Saharan Africa | E60: ='Compound Alert'!E207 -> IDA | F60: ='Compound Alert'!F207 -> 0 | G60: =IF($B$8="Overall Alert",'Compound Alert'!G207,IF($B$8="Underlying Vulnerability",'Compound Alert'!J207,IF($B$8="Emerging Threat",'Compound Alert'!M207))) -> 1.5 | H60: =IF($B$8="Overall Alert",'Compound Alert'!H207,IF($B$8="Underlying Vulnerability",'Compound Alert'!K207,IF($B$8="Emerging Threat",'Compound Alert'!N207))) -> 1.5 | I60: =ROUNDDOWN(G60,0) -> 1 | J60: =IF( $B$8="Overall Alert",IF( 'Compound Alert'!R207 >= 7, "HIGH",IF( 'Compound Alert'!R207 >= 5, "MED","LOW")), IF( $B$8="Underlying Vulnerability", IF( 'Compound Alert'!Y207 >= 10, "HIGH",IF( 'Compound Alert'!Y207 >= 7, "MED","LOW")),IF( $B$8="Emerging Threat", IF( 'Compound Alert'!AF207 >= 10, "HIGH",IF( 'Compound Alert'!AF207 >= 7, "MED","LOW"))))) -> LOW | K60: =IF( $B$8="Overall Alert",IF( 'Compound Alert'!S207 >= 7, "HIGH",IF( 'Compound Alert'!S207 >= 5, "MED","LOW")), IF( $B$8="Underlying Vulnerability", IF( 'Compound Alert'!Z207 >= 10, "HIGH",IF( 'Compound Alert'!Z207 >= 7, "MED","LOW")),IF( $B$8="Emerging Threat", IF( 'Compound Alert'!AG207 >= 10, "HIGH",IF( 'Compound Alert'!AG207 >= 7, "MED","LOW"))))) -> MED | L60: =IF( $B$8="Overall Alert",IF( 'Compound Alert'!T207 >= 7, "HIGH",IF( 'Compound Alert'!T207 >= 5, "MED","LOW")), IF( $B$8="Underlying Vulnerability", IF( 'Compound Alert'!AA207 >= 10, "HIGH",IF( 'Compound Alert'!AA207 >= 7, "MED","LOW")),IF( $B$8="Emerging Threat", IF( 'Compound Alert'!AH207 >= 10, "HIGH",IF( 'Compound Alert'!AH207 >= 7, "MED","LOW"))))) -> LOW | M60: =IF( $B$8="Overall Alert",IF( 'Compound Alert'!U207 >= 7, "HIGH",IF( 'Compound Alert'!U207 >= 5, "MED","LOW")), IF( $B$8="Underlying Vulnerability", IF( 'Compound Alert'!AB207 >= 10, "HIGH",IF( 'Compound Alert'!AB207 >= 7, "MED","LOW")),IF( $B$8="Emerging Threat", IF( 'Compound Alert'!AI207 >= 10, "HIGH",IF( 'Compound Alert'!AI207 >= 7, "MED","LOW"))))) -> LOW | N60: =IF( $B$8="Overall Alert",IF( 'Compound Alert'!V207 >= 7, "HIGH",IF( 'Compound Alert'!V207 >= 5, "MED","LOW")), IF( $B$8="Underlying Vulnerability", IF( 'Compound Alert'!AC207 >= 10, "HIGH",IF( 'Compound Alert'!AC207 >= 7, "MED","LOW")),IF( $B$8="Emerging Threat", IF( 'Compound Alert'!AJ207 >= 10, "HIGH",IF( 'Compound Alert'!AJ207 >= 7, "MED","LOW"))))) -> LOW | O60: =IF( $B$8="Overall Alert",IF( 'Compound Alert'!W207 >= 7, "HIGH",IF( 'Compound Alert'!W207 >= 5, "MED","LOW")), IF( $B$8="Underlying Vulnerability", IF( 'Compound Alert'!AD207 >= 10, "HIGH",IF( 'Compound Alert'!AD207 >= 7, "MED","LOW")),IF( $B$8="Emerging Threat", IF( 'Compound Alert'!AK207 >= 10, "HIGH",IF( 'Compound Alert'!AK207 >= 7, "MED","LOW"))))) -> HIGH
A61: 20 | B61: ='Compound Alert'!B7 -> Afghanistan | C61: ='Compound Alert'!C7 -> AFG | D61: ='Compound Alert'!D7 -> SAS South Asia | E61: ='Compound Alert'!E7 -> IDA | F61: ='Compound Alert'!F7 -> 2 | G61: =IF($B$8="Overall Alert",'Compound Alert'!G7,IF($B$8="Underlying Vulnerability",'Compound Alert'!J7,IF($B$8="Emerging Threat",'Compound Alert'!M7))) -> 4 | H61: =IF($B$8="Overall Alert",'Compound Alert'!H7,IF($B$8="Underlying Vulnerability",'Compound Alert'!K7,IF($B$8="Emerging Threat",'Compound Alert'!N7))) -> 4 | I61: =ROUNDDOWN(G61,0) -> 4 | J61: =IF( $B$8="Overall Alert",IF( 'Compound Alert'!R7 >= 7, "HIGH",IF( 'Compound Alert'!R7 >= 5, "MED","LOW")), IF( $B$8="Underlying Vulnerability", IF( 'Compound Alert'!Y7 >= 10, "HIGH",IF( 'Compound Alert'!Y7 >= 7, "MED","LOW")),IF( $B$8="Emerging Threat", IF( 'Compound Alert'!AF7 >= 10, "HIGH",IF( 'Compound Alert'!AF7 >= 7, "MED","LOW"))))) -> LOW | K61: =IF( $B$8="Overall Alert",IF( 'Compound Alert'!S7 >= 7, "HIGH",IF( 'Compound Alert'!S7 >= 5, "MED","LOW")), IF( $B$8="Underlying Vulnerability", IF( 'Compound Alert'!Z7 >= 10, "HIGH",IF( 'Compound Alert'!Z7 >= 7, "MED","LOW")),IF( $B$8="Emerging Threat", IF( 'Compound Alert'!AG7 >= 10, "HIGH",IF( 'Compound Alert'!AG7 >= 7, "MED","LOW"))))) -> HIGH | L61: =IF( $B$8="Overall Alert",IF( 'Compound Alert'!T7 >= 7, "HIGH",IF( 'Compound Alert'!T7 >= 5, "MED","LOW")), IF( $B$8="Underlying Vulnerability", IF( 'Compound Alert'!AA7 >= 10, "HIGH",IF( 'Compound Alert'!AA7 >= 7, "MED","LOW")),IF( $B$8="Emerging Threat", IF( 'Compound Alert'!AH7 >= 10, "HIGH",IF( 'Compound Alert'!AH7 >= 7, "MED","LOW"))))) -> HIGH | M61: =IF( $B$8="Overall Alert",IF( 'Compound Alert'!U7 >= 7, "HIGH",IF( 'Compound Alert'!U7 >= 5, "MED","LOW")), IF( $B$8="Underlying Vulnerability", IF( 'Compound Alert'!AB7 >= 10, "HIGH",IF( 'Compound Alert'!AB7 >= 7, "MED","LOW")),IF( $B$8="Emerging Threat", IF( 'Compound Alert'!AI7 >= 10, "HIGH",IF( 'Compound Alert'!AI7 >= 7, "MED","LOW"))))) -> LOW | N61: =IF( $B$8="Overall Alert",IF( 'Compound Alert'!V7 >= 7, "HIGH",IF( 'Compound Alert'!V7 >= 5, "MED","LOW")), IF( $B$8="Underlying Vulnerability", IF( 'Compound Alert'!AC7 >= 10, "HIGH",IF( 'Compound Alert'!AC7 >= 7, "MED","LOW")),IF( $B$8="Emerging Threat", IF( 'Compound Alert'!AJ7 >= 10, "HIGH",IF( 'Compound Alert'!AJ7 >= 7, "MED","LOW"))))) -> HIGH | O61: =IF( $B$8="Overall Alert",IF( 'Compound Alert'!W7 >= 7, "HIGH",IF( 'Compound Alert'!W7 >= 5, "MED","LOW")), IF( $B$8="Underlying Vulnerability", IF( 'Compound Alert'!AD7 >= 10, "HIGH",IF( 'Compound Alert'!AD7 >= 7, "MED","LOW")),IF( $B$8="Emerging Threat", IF( 'Compound Alert'!AK7 >= 10, "HIGH",IF( 'Compound Alert'!AK7 >= 7, "MED","LOW"))))) -> HIGH
